<?xml version="1.0"?>

<gazebo>
  <plugin name="gazebo_ros_control" filename="libgazebo_ros_control.so">
    <robotNamespace>/</robotNamespace>
  </plugin>
</gazebo>


    <link name='left_wall_beam'>
      <pose> 5.5 0 3.75 0 0 0</pose>

      <collision name='collision_lwb'>
        <geometry>
          <box>
            <size> 1 10 0.5 </size>
          </box>
        </geometry>
      </collision>


      <visual name='visual_lwb'>
        <geometry>
          <box>
            <size> 1 10 0.5 </size>
          </box>
        </geometry>
      </visual>
    </link>

    <link name='left_wall_beam_front_support'>
      <pose> 5.5 5 2 0 0 0</pose>

      <collision name='collision_lwbfs'>
        <geometry>
          <box>
            <size> 1 1 4 </size>
          </box>
        </geometry>
      </collision>


      <visual name='visual_lwbfs'>
        <geometry>
          <box>
            <size> 1 1 4 </size>
          </box>
        </geometry>
      </visual>
    </link>

    <link name='left_wall_beam_back_support'>
      <pose> 5.5 -5 2 0 0 0</pose>

      <collision name='collision_lwbbs'>
        <geometry>
          <box>
            <size> 1 1 4 </size>
          </box>
        </geometry>
      </collision>


      <visual name='visual_lwbbs'>
        <geometry>
          <box>
            <size> 1 1 4 </size>
          </box>
        </geometry>
      </visual>
    </link>

    <link name='right_wall_beam'>
      <pose> -5.5 0 3.75 0 0 0</pose>

      <collision name='collision_rwb'>
        <geometry>
          <box>
            <size> 1 10 0.5 </size>
          </box>
        </geometry>
      </collision>


      <visual name='visual_rwb'>
        <geometry>
          <box>
            <size> 1 10 0.5 </size>
          </box>
        </geometry>
      </visual>
    </link>

    <link name='right_wall_beam_front_support'>
      <pose> -5.5 5 2 0 0 0</pose>

      <collision name='collision_rwbfs'>
        <geometry>
          <box>
            <size> 1 1 4 </size>
          </box>
        </geometry>
      </collision>


      <visual name='visual_rwbfs'>
        <geometry>
          <box>
            <size> 1 1 4 </size>
          </box>
        </geometry>
      </visual>
    </link>

    <link name='right_wall_beam_back_support'>
      <pose> -5.5 -5 2 0 0 0</pose>

      <collision name='collision_rwbbs'>
        <geometry>
          <box>
            <size> 1 1 4 </size>
          </box>
        </geometry>
      </collision>


      <visual name='visual_rwbbs'>
        <geometry>
          <box>
            <size> 1 1 4 </size>
          </box>
        </geometry>
      </visual>
    </link>




    <link name='bottom_beam'>
      <pose> 0 0 4.25 0 0 0</pose>

      <collision name='collision_bb'>
        <geometry>
          <box>
            <size> 11 1 0.1 </size>
          </box>
        </geometry>
      </collision>


      <visual name='visual_bb'>
        <geometry>
          <box>
            <size> 11 1 0.1 </size>
          </box>
        </geometry>
      </visual>
    </link>

    <link name='midsection'>
      <pose> 0 0 4.65 0 0 0</pose>

      <collision name='collision_ms'>
        <geometry>
          <box>
            <size> 11 0.1 0.75 </size>
          </box>
        </geometry>
      </collision>


      <visual name='visual_ms'>
        <geometry>
          <box>
            <size> 11 0.1 0.75 </size>
          </box>
        </geometry>
      </visual>
    </link>

    <link name='top_beam'>
      <pose> 0 0 5.0 0 0 0</pose>

      <collision name='collision_tb'>
        <geometry>
          <box>
            <size> 11 1 0.1 </size>
          </box>
        </geometry>
      </collision>


      <visual name='visual_tb'>
        <geometry>
          <box>
            <size> 11 1 0.1 </size>
          </box>
        </geometry>
      </visual>
    </link>

    <link name='trolly_leftwall'>
      <pose> 0 0.6 4.25 0 0 0</pose>

      <collision name='collision_tr_lf'>
        <geometry>
          <box>
            <size> 1 0.1 1 </size>
          </box>
        </geometry>
      </collision>


      <visual name='visual_tr_lf'>
        <geometry>
          <box>
            <size> 1 0.1 1 </size>
          </box>
        </geometry>
      </visual>
    </link>

    <link name='trolly_rightwall'>
      <pose> 0 -0.6 4.25 0 0 0</pose>

      <collision name='collision_tr_rw'>
        <geometry>
          <box>
            <size> 1 0.1 1 </size>
          </box>
        </geometry>
      </collision>


      <visual name='visual_tr_rw'>
        <geometry>
          <box>
            <size> 1 0.1 1 </size>
          </box>
        </geometry>
      </visual>
    </link>

    <link name='trolly_floor'>
      <pose> 0 0 3.8 0 0 0</pose>

      <collision name='collision_tr_fl'>
        <geometry>
          <box>
            <size> 1 1.1 0.1 </size>
          </box>
        </geometry>
      </collision>


      <visual name='visual_tr_fl'>
        <geometry>
          <box>
            <size> 1 1.2 0.1 </size>
          </box>
        </geometry>
      </visual>
    </link>


    <link name="left_front_wheel">
      <pose>0.35 0.45 4.5 1.57057 0 0</pose>
      <collision name="collision_lfw">
        <geometry>
          <cylinder>
            <radius>0.2</radius>
            <length>0.2</length>
          </cylinder>
        </geometry>
      </collision>
      <visual name="lfw">
        <geometry>
          <cylinder>
            <radius>0.2</radius>
            <length>0.2</length>
          </cylinder>
        </geometry>
      </visual>
    </link>

    <joint type="revolute" name="left_front_wheel_hinge">
      <pose>0 0.1 0 0 0 0</pose>
      <child>left_front_wheel</child>
      <parent>trolly_leftwall</parent>
      <axis>
        <xyz>0 1 0</xyz>
      </axis>
    </joint>


    <link name="left_back_wheel">
      <pose> -0.35 0.45 4.5 1.57057 0 0</pose>
      <collision name="collision_lbw">
        <geometry>
          <cylinder>
            <radius>0.2</radius>
            <length>0.2</length>
          </cylinder>
        </geometry>
      </collision>
      <visual name="lbw">
        <geometry>
          <cylinder>
            <radius>0.2</radius>
            <length>0.2</length>
          </cylinder>
        </geometry>
      </visual>
    </link>

    <joint type="revolute" name="left_back_wheel_hinge">
      <pose> 0 0.1 0 0 0 0</pose>
      <child>left_back_wheel</child>
      <parent>trolly_leftwall</parent>
      <axis>
        <xyz>0 1 0</xyz>
      </axis>
    </joint>

    <link name="right_front_wheel">
      <pose> 0.35 -0.45 4.5 1.57057 0 0</pose>
      <collision name="collision_rfw">
        <geometry>
          <cylinder>
            <radius>0.2</radius>
            <length>0.2</length>
          </cylinder>
        </geometry>
      </collision>
      <visual name="rfw">
        <geometry>
          <cylinder>
            <radius>0.2</radius>
            <length>0.2</length>
          </cylinder>
        </geometry>
      </visual>
    </link>

    <joint type="revolute" name="right_front_wheel_hinge">
      <pose>0 -0.1 0 0 0 0</pose>
      <child>right_front_wheel</child>
      <parent>trolly_rightwall</parent>
      <axis>
        <xyz>0 1 0</xyz>
      </axis>
    </joint>

    <link name="right_back_wheel">
      <pose> -0.35 -0.45 4.5 1.57057 0 0</pose>
      <collision name="collision_rbw">
        <geometry>
          <cylinder>
            <radius>0.2</radius>
            <length>0.2</length>
          </cylinder>
        </geometry>
      </collision>
      <visual name="rbw">
        <geometry>
          <cylinder>
            <radius>0.2</radius>
            <length>0.2</length>
          </cylinder>
        </geometry>
      </visual>
    </link>

    <joint type="revolute" name="right_back_wheel_hinge">
      <pose> 0 -0.1 0 0 0 0</pose>
      <child>right_back_wheel</child>
      <parent>trolly_rightwall</parent>
      <axis>
        <xyz>0 1 0</xyz>
      </axis>
    </joint>
